Workbook

Sheet Leer Comentarios
B3: Saque los pozos en reserva de gas
B5: 356 pozos en la lista de YPF
B7: Se sacaron los pozos que visualizaron oportunidades (65 pozos)
B9: Se sacan los pozos de 1,5 de neta sacados del total
B11: Se sacan los pozos fuera del total hace mas de 6 meses y 1 año

Sheet Tabla General
A3: Etiquetas de fila | B3: Cuenta de Pozo largo
A4: ABA O NETA +1,5 | B4: 19
A5: ABA O OPORTUNIDAD | B5: 32
A6: ABA ULT 6 MESES | B6: 38
A7: ABA ULT AÑO | B7: 47
A8: ABANDONADO | B8: 435
A9: ABANDONAR | B9: 528
A10: FALTA ABA DEFINITIVO | B10: 1
A11: LISTA YPF | B11: 351
A12: NO ABANDONAR | B12: 1528
A13: SACAR DE LA LISTA YPF | B13: 5
A14: Total general | B14: 2984

Sheet E #1
B2: Saque los pozos en reserva de gas | G2: 984 POZOS
B3: Se sacaron los pozos que visualizaron oportunidades (65 pozos)
B6: Accion | C6: (Varios elementos)
B8: Etiquetas de fila
B9: CG-595[00]a
B10: CnE-940[00]a
B11: LH-1[00]a
B12: LH-1114[00]a
B13: LH-291[00]
B14: YPF.SC.BB.a-104
B15: YPF.SC.BB.a-107
B16: YPF.SC.BB.a-29
B17: YPF.SC.BB.a-30
B18: YPF.SC.BB.a-33
B19: YPF.SC.BB.a-69
... B993: Total general

Sheet E #2
B2: Saque los pozos en reserva de gas | G2: 946 POZOS
B3: Se sacaron los pozos que visualizaron oportunidades (65 pozos)
B4: Se sacan los pozos fuera del total hace mas de 6 meses
B6: Accion | C6: (Varios elementos)
B8: Etiquetas de fila
B9: CG-595[00]a
B10: CnE-940[00]a
B11: LH-1[00]a
B12: LH-1114[00]a
B13: LH-291[00]
B14: YPF.SC.BB.a-104
B15: YPF.SC.BB.a-107
B16: YPF.SC.BB.a-29
B17: YPF.SC.BB.a-30
B18: YPF.SC.BB.a-33
B19: YPF.SC.BB.a-69
... B955: Total general

Sheet E #3
B2: Saque los pozos en reserva de gas | G2: 880 POZOS
B3: Se sacaron los pozos que visualizaron oportunidades (65 pozos)
B4: Se sacan los pozos de 1,5 de neta sacados del total
B5: Se sacan los pozos fuera del total hace mas de 6 meses y 1 año
B7: Accion | C7: (Varios elementos)
B9: Etiquetas de fila
B10: CG-595[00]a
B11: CnE-940[00]a
B12: LH-1[00]a
B13: LH-1114[00]a
B14: LH-291[00]
B15: YPF.SC.BB.a-104
B16: YPF.SC.BB.a-107
B17: YPF.SC.BB.a-29
B18: YPF.SC.BB.a-30
B19: YPF.SC.BB.a-33
B20: YPF.SC.BB.a-7
... B890: Total general

Sheet Lista
B2: Pozo largo | C2: Pozo | D2: Activo | E2: Estado TOW | F2: SE | G2: Accion | H2: Bloque | I2: Lista YPF | J2: Oportunidad | K2: Ult Control | L2: Salio del total
B3: YPF.SC.CnE-1284 | C3: CnE-1284 | D3: Las Heras CG - Canadon Escondida | E3: Espera Equipo Reparación | F3: Bombeo Mecánico | G3: ABA ULT 6 MESES | H3: Barranca Baya Bloque 30 | I3: =IFERROR(VLOOKUP(Consulta1[[#This Row],[Pozo largo]],'Lista YPF'!$B$3:$C$358,2,FALSE),"NO") -> NO | J3: =IFERROR(VLOOKUP(Consulta1[[#This Row],[Pozo]],'Lista Oportunidades'!B:C,2,FALSE),"NO") -> NO | K3: =IFERROR(VLOOKUP(Consulta1[[#This Row],[Pozo largo]],Controles!B:H,7,FALSE),"NO") -> 0.66 | L3: =IFERROR(VLOOKUP(Consulta1[[#This Row],[Pozo largo]],Controles!B:J,9,FALSE),"NO") -> Ultimos 6 meses
B4: YPF.SC.CnE-1373 | C4: CnE-1373 | D4: Las Heras CG - Canadon Escondida | E4: Produciendo | F4: Bombeo Mecánico | G4: NO ABANDONAR | H4: Barranca Baya Bloque 30 | I4: =IFERROR(VLOOKUP(Consulta1[[#This Row],[Pozo largo]],'Lista YPF'!$B$3:$C$358,2,FALSE),"NO") -> NO | J4: =IFERROR(VLOOKUP(Consulta1[[#This Row],[Pozo]],'Lista Oportunidades'!B:C,2,FALSE),"NO") -> Oportunidad | K4: =IFERROR(VLOOKUP(Consulta1[[#This Row],[Pozo largo]],Controles!B:H,7,FALSE),"NO") -> 1 | L4: =IFERROR(VLOOKUP(Consulta1[[#This Row],[Pozo largo]],Controles!B:J,9,FALSE),"NO") -> 0
B5: YPF.SC.CG-985 | C5: CG-985 | D5: Las Heras CG - Canadon Escondida | E5: Produciendo | F5: Bombeo Mecánico | G5: NO ABANDONAR | H5: Barranca Baya Cerro Grande Noroeste | I5: =IFERROR(VLOOKUP(Consulta1[[#This Row],[Pozo largo]],'Lista YPF'!$B$3:$C$358,2,FALSE),"NO") -> NO | J5: =IFERROR(VLOOKUP(Consulta1[[#This Row],[Pozo]],'Lista Oportunidades'!B:C,2,FALSE),"NO") -> NO | K5: =IFERROR(VLOOKUP(Consulta1[[#This Row],[Pozo largo]],Controles!B:H,7,FALSE),"NO") -> 4.962 | L5: =IFERROR(VLOOKUP(Consulta1[[#This Row],[Pozo largo]],Controles!B:J,9,FALSE),"NO") -> 0
B6: YPF.SC.CnE-1464 | C6: CnE-1464a | D6: Las Heras CG - Canadon Escondida | E6: Produciendo | F6: Bombeo Mecánico | G6: NO ABANDONAR | H6: Barranca Baya Bloque 30 | I6: =IFERROR(VLOOKUP(Consulta1[[#This Row],[Pozo largo]],'Lista YPF'!$B$3:$C$358,2,FALSE),"NO") -> NO | J6: =IFERROR(VLOOKUP(Consulta1[[#This Row],[Pozo]],'Lista Oportunidades'!B:C,2,FALSE),"NO") -> NO | K6: =IFERROR(VLOOKUP(Consulta1[[#This Row],[Pozo largo]],Controles!B:H,7,FALSE),"NO") -> 4.25 | L6: =IFERROR(VLOOKUP(Consulta1[[#This Row],[Pozo largo]],Controles!B:J,9,FALSE),"NO") -> 0
B7: YPF.SC.CnE-329 | C7: CnE-329 | D7: Las Heras CG - Canadon Escondida | E7: Produciendo | F7: Bombeo Mecánico | G7: NO ABANDONAR | H7: Barranca Baya Bloque 36 | I7: =IFERROR(VLOOKUP(Consulta1[[#This Row],[Pozo largo]],'Lista YPF'!$B$3:$C$358,2,FALSE),"NO") -> NO | J7: =IFERROR(VLOOKUP(Consulta1[[#This Row],[Pozo]],'Lista Oportunidades'!B:C,2,FALSE),"NO") -> NO | K7: =IFERROR(VLOOKUP(Consulta1[[#This Row],[Pozo largo]],Controles!B:H,7,FALSE),"NO") -> 0.837 | L7: =IFERROR(VLOOKUP(Consulta1[[#This Row],[Pozo largo]],Controles!B:J,9,FALSE),"NO") -> 0
B8: YPF.SC.CnE.a-371 | C8: CnE-371 | D8: Las Heras CG - Canadon Escondida | E8: Reserva Recuperación Secundaria | F8: Pistoneo | G8: ABA ULT AÑO | H8: Barranca Baya Bloque 36 | I8: =IFERROR(VLOOKUP(Consulta1[[#This Row],[Pozo largo]],'Lista YPF'!$B$3:$C$358,2,FALSE),"NO") -> NO | J8: =IFERROR(VLOOKUP(Consulta1[[#This Row],[Pozo]],'Lista Oportunidades'!B:C,2,FALSE),"NO") -> NO | K8: =IFERROR(VLOOKUP(Consulta1[[#This Row],[Pozo largo]],Controles!B:H,7,FALSE),"NO") -> 0.01 | L8: =IFERROR(VLOOKUP(Consulta1[[#This Row],[Pozo largo]],Controles!B:J,9,FALSE),"NO") -> Ultimo Año
B9: YPF.SC.CnE.a-373 | C9: CnE-373 | D9: Las Heras CG - Canadon Escondida | E9: Produciendo | F9: Inyección | G9: NO ABANDONAR | H9: Barranca Baya Bloque 36 | I9: =IFERROR(VLOOKUP(Consulta1[[#This Row],[Pozo largo]],'Lista YPF'!$B$3:$C$358,2,FALSE),"NO") -> NO | J9: =IFERROR(VLOOKUP(Consulta1[[#This Row],[Pozo]],'Lista Oportunidades'!B:C,2,FALSE),"NO") -> NO | K9: =IFERROR(VLOOKUP(Consulta1[[#This Row],[Pozo largo]],Controles!B:H,7,FALSE),"NO") -> 0 | L9: =IFERROR(VLOOKUP(Consulta1[[#This Row],[Pozo largo]],Controles!B:J,9,FALSE),"NO") -> 0
B10: YPF.SC.CnE.a-477 | C10: CnE-477 | D10: Las Heras CG - Canadon Escondida | E10: Abandono Permanente | F10: No Posee | G10: ABANDONADO | H10: Barranca Baya Bloque 37 | I10: =IFERROR(VLOOKUP(Consulta1[[#This Row],[Pozo largo]],'Lista YPF'!$B$3:$C$358,2,FALSE),"NO") -> NO | J10: =IFERROR(VLOOKUP(Consulta1[[#This Row],[Pozo]],'Lista Oportunidades'!B:C,2,FALSE),"NO") -> NO | K10: =IFERROR(VLOOKUP(Consulta1[[#This Row],[Pozo largo]],Controles!B:H,7,FALSE),"NO") -> NO | L10: =IFERROR(VLOOKUP(Consulta1[[#This Row],[Pozo largo]],Controles!B:J,9,FALSE),"NO") -> NO
B11: YPF.SC.CnE.a-496 | C11: CnE-496 | D11: Las Heras CG - Canadon Escondida | E11: Produciendo | F11: Inyección | G11: NO ABANDONAR | H11: Barranca Baya | I11: =IFERROR(VLOOKUP(Consulta1[[#This Row],[Pozo largo]],'Lista YPF'!$B$3:$C$358,2,FALSE),"NO") -> NO | J11: =IFERROR(VLOOKUP(Consulta1[[#This Row],[Pozo]],'Lista Oportunidades'!B:C,2,FALSE),"NO") -> NO | K11: =IFERROR(VLOOKUP(Consulta1[[#This Row],[Pozo largo]],Controles!B:H,7,FALSE),"NO") -> 0 | L11: =IFERROR(VLOOKUP(Consulta1[[#This Row],[Pozo largo]],Controles!B:J,9,FALSE),"NO") -> 0
B12: YPF.SC.CnE-506 | C12: CnE-506 | D12: Las Heras CG - Canadon Escondida | E12: Produciendo | F12: Inyección | G12: NO ABANDONAR | H12: Barranca Baya Bloque 36 | I12: =IFERROR(VLOOKUP(Consulta1[[#This Row],[Pozo largo]],'Lista YPF'!$B$3:$C$358,2,FALSE),"NO") -> NO | J12: =IFERROR(VLOOKUP(Consulta1[[#This Row],[Pozo]],'Lista Oportunidades'!B:C,2,FALSE),"NO") -> NO | K12: =IFERROR(VLOOKUP(Consulta1[[#This Row],[Pozo largo]],Controles!B:H,7,FALSE),"NO") -> 0 | L12: =IFERROR(VLOOKUP(Consulta1[[#This Row],[Pozo largo]],Controles!B:J,9,FALSE),"NO") -> 0
B13: YPF.SC.CnE-554 | C13: CnE-554 | D13: Las Heras CG - Canadon Escondida | E13: Produciendo | F13: Pistoneo | G13: NO ABANDONAR | H13: Barranca Baya | I13: =IFERROR(VLOOKUP(Consulta1[[#This Row],[Pozo largo]],'Lista YPF'!$B$3:$C$358,2,FALSE),"NO") -> NO | J13: =IFERROR(VLOOKUP(Consulta1[[#This Row],[Pozo]],'Lista Oportunidades'!B:C,2,FALSE),"NO") -> NO | K13: =IFERROR(VLOOKUP(Consulta1[[#This Row],[Pozo largo]],Controles!B:H,7,FALSE),"NO") -> 0.067 | L13: =IFERROR(VLOOKUP(Consulta1[[#This Row],[Pozo largo]],Controles!B:J,9,FALSE),"NO") -> 0
B14: YPF.SC.CnE.a-599 | C14: CnE-599 | D14: Las Heras CG - Canadon Escondida | E14: Produciendo | F14: Pistoneo | G14: NO ABANDONAR | H14: Barranca Baya Bloque 36 | I14: =IFERROR(VLOOKUP(Consulta1[[#This Row],[Pozo largo]],'Lista YPF'!$B$3:$C$358,2,FALSE),"NO") -> NO | J14: =IFERROR(VLOOKUP(Consulta1[[#This Row],[Pozo]],'Lista Oportunidades'!B:C,2,FALSE),"NO") -> NO | K14: =IFERROR(VLOOKUP(Consulta1[[#This Row],[Pozo largo]],Controles!B:H,7,FALSE),"NO") -> 0.029 | L14: =IFERROR(VLOOKUP(Consulta1[[#This Row],[Pozo largo]],Controles!B:J,9,FALSE),"NO") -> 0
... B34: YPF.SC.LH-95 | C34: LH-95 | D34: Las Heras CG - Canadon Escondida | E34: Produciendo | F34: Bombeo Mecánico | G34: NO ABANDONAR | H34: Las Heras Cerro Grande Sur | I34: =IFERROR(VLOOKUP(Consulta1[[#This Row],[Pozo largo]],'Lista YPF'!$B$3:$C$358,2,FALSE),"NO") -> NO | J34: =IFERROR(VLOOKUP(Consulta1[[#This Row],[Pozo]],'Lista Oportunidades'!B:C,2,FALSE),"NO") -> NO | K34: =IFERROR(VLOOKUP(Consulta1[[#This Row],[Pozo largo]],Controles!B:H,7,FALSE),"NO") -> 1.222 | L34: =IFERROR(VLOOKUP(Consulta1[[#This Row],[Pozo largo]],Controles!B:J,9,FALSE),"NO") -> 0
B35: CR-1[00] | C35: CR-1 | D35: Las Heras CG - Canadon Escondida | E35: Abandono Permanente | F35: No Posee | G35: ABANDONADO | I35: =IFERROR(VLOOKUP(Consulta1[[#This Row],[Pozo largo]],'Lista YPF'!$B$3:$C$358,2,FALSE),"NO") -> NO | J35: =IFERROR(VLOOKUP(Consulta1[[#This Row],[Pozo]],'Lista Oportunidades'!B:C,2,FALSE),"NO") -> NO | K35: =IFERROR(VLOOKUP(Consulta1[[#This Row],[Pozo largo]],Controles!B:H,7,FALSE),"NO") -> NO | L35: =IFERROR(VLOOKUP(Consulta1[[#This Row],[Pozo largo]],Controles!B:J,9,FALSE),"NO") -> NO
B36: YPF.SC.LH-204 | C36: LH-204 | D36: Las Heras CG - Canadon Escondida | E36: Abandono Permanente | F36: No Posee | G36: ABANDONADO | H36: Las Heras Bloque 2 | I36: =IFERROR(VLOOKUP(Consulta1[[#This Row],[Pozo largo]],'Lista YPF'!$B$3:$C$358,2,FALSE),"NO") -> NO | J36: =IFERROR(VLOOKUP(Consulta1[[#This Row],[Pozo]],'Lista Oportunidades'!B:C,2,FALSE),"NO") -> NO | K36: =IFERROR(VLOOKUP(Consulta1[[#This Row],[Pozo largo]],Controles!B:H,7,FALSE),"NO") -> NO | L36: =IFERROR(VLOOKUP(Consulta1[[#This Row],[Pozo largo]],Controles!B:J,9,FALSE),"NO") -> NO
B37: YPF.SC.LH-298 | C37: LH-298 | D37: Las Heras CG - Canadon Escondida | E37: Reserva Recuperación Secundaria | F37: No Posee | G37: ABANDONAR | H37: Las Heras Central Sur | I37: =IFERROR(VLOOKUP(Consulta1[[#This Row],[Pozo largo]],'Lista YPF'!$B$3:$C$358,2,FALSE),"NO") -> NO | J37: =IFERROR(VLOOKUP(Consulta1[[#This Row],[Pozo]],'Lista Oportunidades'!B:C,2,FALSE),"NO") -> NO | K37: =IFERROR(VLOOKUP(Consulta1[[#This Row],[Pozo largo]],Controles!B:H,7,FALSE),"NO") -> NO | L37: =IFERROR(VLOOKUP(Consulta1[[#This Row],[Pozo largo]],Controles!B:J,9,FALSE),"NO") -> NO
B38: YPF.SC.LH-471 | C38: LH-471 | D38: Las Heras CG - Canadon Escondida | E38: Abandono Permanente | F38: No Posee | G38: ABANDONADO | H38: Las Heras Central Sur | I38: =IFERROR(VLOOKUP(Consulta1[[#This Row],[Pozo largo]],'Lista YPF'!$B$3:$C$358,2,FALSE),"NO") -> NO | J38: =IFERROR(VLOOKUP(Consulta1[[#This Row],[Pozo]],'Lista Oportunidades'!B:C,2,FALSE),"NO") -> NO | K38: =IFERROR(VLOOKUP(Consulta1[[#This Row],[Pozo largo]],Controles!B:H,7,FALSE),"NO") -> NO | L38: =IFERROR(VLOOKUP(Consulta1[[#This Row],[Pozo largo]],Controles!B:J,9,FALSE),"NO") -> NO
B39: YPF.SC.LH-472 | C39: LH-472 | D39: Las Heras CG - Canadon Escondida | E39: Abandono Permanente | F39: No Posee | G39: ABANDONADO | H39: Las Heras Central Sur | I39: =IFERROR(VLOOKUP(Consulta1[[#This Row],[Pozo largo]],'Lista YPF'!$B$3:$C$358,2,FALSE),"NO") -> NO | J39: =IFERROR(VLOOKUP(Consulta1[[#This Row],[Pozo]],'Lista Oportunidades'!B:C,2,FALSE),"NO") -> NO | K39: =IFERROR(VLOOKUP(Consulta1[[#This Row],[Pozo largo]],Controles!B:H,7,FALSE),"NO") -> 0.183 | L39: =IFERROR(VLOOKUP(Consulta1[[#This Row],[Pozo largo]],Controles!B:J,9,FALSE),"NO") -> 0
B40: YPF.SC.CG-92 | C40: CG-92 | D40: Las Heras CG - Canadon Escondida | E40: En Estudio | F40: No Posee | G40: LISTA YPF | H40: Barranca Baya Bloque 26 | I40: =IFERROR(VLOOKUP(Consulta1[[#This Row],[Pozo largo]],'Lista YPF'!$B$3:$C$358,2,FALSE),"NO") -> En lista de Abandono | J40: =IFERROR(VLOOKUP(Consulta1[[#This Row],[Pozo]],'Lista Oportunidades'!B:C,2,FALSE),"NO") -> NO | K40: =IFERROR(VLOOKUP(Consulta1[[#This Row],[Pozo largo]],Controles!B:H,7,FALSE),"NO") -> 1.08 | L40: =IFERROR(VLOOKUP(Consulta1[[#This Row],[Pozo largo]],Controles!B:J,9,FALSE),"NO") -> 0
B41: YPF.SC.CnE-869 | C41: CnE-869 | D41: Las Heras CG - Canadon Escondida | E41: Espera Equipo Reparación | F41: Pistoneo | G41: ABA ULT 6 MESES | H41: Barranca Baya Bloque 36 | I41: =IFERROR(VLOOKUP(Consulta1[[#This Row],[Pozo largo]],'Lista YPF'!$B$3:$C$358,2,FALSE),"NO") -> NO | J41: =IFERROR(VLOOKUP(Consulta1[[#This Row],[Pozo]],'Lista Oportunidades'!B:C,2,FALSE),"NO") -> NO | K41: =IFERROR(VLOOKUP(Consulta1[[#This Row],[Pozo largo]],Controles!B:H,7,FALSE),"NO") -> 0.096 | L41: =IFERROR(VLOOKUP(Consulta1[[#This Row],[Pozo largo]],Controles!B:J,9,FALSE),"NO") -> Ultimos 6 meses
B42: YPF.SC.LC-630 | C42: LC-630a | D42: Las Heras CG - Canadon Escondida | E42: Abandono Permanente | F42: No Posee | G42: ABANDONADO | H42: Lomas del Cuy- Cerro Grande Noroeste | I42: =IFERROR(VLOOKUP(Consulta1[[#This Row],[Pozo largo]],'Lista YPF'!$B$3:$C$358,2,FALSE),"NO") -> NO | J42: =IFERROR(VLOOKUP(Consulta1[[#This Row],[Pozo]],'Lista Oportunidades'!B:C,2,FALSE),"NO") -> NO | K42: =IFERROR(VLOOKUP(Consulta1[[#This Row],[Pozo largo]],Controles!B:H,7,FALSE),"NO") -> 0.91 | L42: =IFERROR(VLOOKUP(Consulta1[[#This Row],[Pozo largo]],Controles!B:J,9,FALSE),"NO") -> 0
B43: YPF.SC.LH-972 | C43: LH-972a | D43: Las Heras CG - Canadon Escondida | E43: Produciendo | F43: Bombeo Mecánico | G43: NO ABANDONAR | H43: Las Heras Las Heras Bloque 3 | I43: =IFERROR(VLOOKUP(Consulta1[[#This Row],[Pozo largo]],'Lista YPF'!$B$3:$C$358,2,FALSE),"NO") -> NO | J43: =IFERROR(VLOOKUP(Consulta1[[#This Row],[Pozo]],'Lista Oportunidades'!B:C,2,FALSE),"NO") -> NO | K43: =IFERROR(VLOOKUP(Consulta1[[#This Row],[Pozo largo]],Controles!B:H,7,FALSE),"NO") -> 0.8 | L43: =IFERROR(VLOOKUP(Consulta1[[#This Row],[Pozo largo]],Controles!B:J,9,FALSE),"NO") -> 0
B44: YPF.SC.CnE-1112 | C44: CnE-1112 | D44: Las Heras CG - Canadon Escondida | E44: Espera Equipo Reparación | F44: Bombeo Mecánico | G44: ABA ULT 6 MESES | H44: Barranca Baya Bloque 30 | I44: =IFERROR(VLOOKUP(Consulta1[[#This Row],[Pozo largo]],'Lista YPF'!$B$3:$C$358,2,FALSE),"NO") -> NO | J44: =IFERROR(VLOOKUP(Consulta1[[#This Row],[Pozo]],'Lista Oportunidades'!B:C,2,FALSE),"NO") -> NO | K44: =IFERROR(VLOOKUP(Consulta1[[#This Row],[Pozo largo]],Controles!B:H,7,FALSE),"NO") -> 1.1 | L44: =IFERROR(VLOOKUP(Consulta1[[#This Row],[Pozo largo]],Controles!B:J,9,FALSE),"NO") -> Ultimos 6 meses
B45: YPF.SC.CnE-1111 | C45: CnE-1111 | D45: Las Heras CG - Canadon Escondida | E45: Produciendo | F45: Bombeo Mecánico | G45: NO ABANDONAR | H45: Barranca Baya Bloque 30 | I45: =IFERROR(VLOOKUP(Consulta1[[#This Row],[Pozo largo]],'Lista YPF'!$B$3:$C$358,2,FALSE),"NO") -> NO | J45: =IFERROR(VLOOKUP(Consulta1[[#This Row],[Pozo]],'Lista Oportunidades'!B:C,2,FALSE),"NO") -> NO | K45: =IFERROR(VLOOKUP(Consulta1[[#This Row],[Pozo largo]],Controles!B:H,7,FALSE),"NO") -> 0.72 | L45: =IFERROR(VLOOKUP(Consulta1[[#This Row],[Pozo largo]],Controles!B:J,9,FALSE),"NO") -> 0
B46: YPF.SC.CnE-1217 | C46: CnE-1217 | D46: Las Heras CG - Canadon Escondida | E46: Produciendo | F46: Inyección | G46: NO ABANDONAR | H46: Barranca Baya Bloque 30 | I46: =IFERROR(VLOOKUP(Consulta1[[#This Row],[Pozo largo]],'Lista YPF'!$B$3:$C$358,2,FALSE),"NO") -> NO | J46: =IFERROR(VLOOKUP(Consulta1[[#This Row],[Pozo]],'Lista Oportunidades'!B:C,2,FALSE),"NO") -> NO | K46: =IFERROR(VLOOKUP(Consulta1[[#This Row],[Pozo largo]],Controles!B:H,7,FALSE),"NO") -> 0 | L46: =IFERROR(VLOOKUP(Consulta1[[#This Row],[Pozo largo]],Controles!B:J,9,FALSE),"NO") -> 0
B47: YPF.SC.CnE-1176 | C47: CnE-1176 | D47: Las Heras CG - Canadon Escondida | E47: Reserva Recuperación Secundaria | F47: Bombeo Mecánico | G47: ABANDONAR | H47: Barranca Baya Bloque 37 | I47: =IFERROR(VLOOKUP(Consulta1[[#This Row],[Pozo largo]],'Lista YPF'!$B$3:$C$358,2,FALSE),"NO") -> NO | J47: =IFERROR(VLOOKUP(Consulta1[[#This Row],[Pozo]],'Lista Oportunidades'!B:C,2,FALSE),"NO") -> NO | K47: =IFERROR(VLOOKUP(Consulta1[[#This Row],[Pozo largo]],Controles!B:H,7,FALSE),"NO") -> 0.165 | L47: =IFERROR(VLOOKUP(Consulta1[[#This Row],[Pozo largo]],Controles!B:J,9,FALSE),"NO") -> 0
... B1416: YPF.SC.CnE-1421 | C1416: CnE-1421a | D1416: Las Heras CG - Canadon Escondida | E1416: Produciendo | F1416: Bombeo Mecánico | G1416: NO ABANDONAR | H1416: Barranca Baya Bloque 30 | I1416: =IFERROR(VLOOKUP(Consulta1[[#This Row],[Pozo largo]],'Lista YPF'!$B$3:$C$358,2,FALSE),"NO") -> NO | J1416: =IFERROR(VLOOKUP(Consulta1[[#This Row],[Pozo]],'Lista Oportunidades'!B:C,2,FALSE),"NO") -> NO | K1416: =IFERROR(VLOOKUP(Consulta1[[#This Row],[Pozo largo]],Controles!B:H,7,FALSE),"NO") -> 2.76 | L1416: =IFERROR(VLOOKUP(Consulta1[[#This Row],[Pozo largo]],Controles!B:J,9,FALSE),"NO") -> 0
B1417: YPF.SC.CG-983 | C1417: CG-983a | D1417: Las Heras CG - Canadon Escondida | E1417: Produciendo | F1417: Bombeo Mecánico | G1417: NO ABANDONAR | I1417: =IFERROR(VLOOKUP(Consulta1[[#This Row],[Pozo largo]],'Lista YPF'!$B$3:$C$358,2,FALSE),"NO") -> NO | J1417: =IFERROR(VLOOKUP(Consulta1[[#This Row],[Pozo]],'Lista Oportunidades'!B:C,2,FALSE),"NO") -> NO | K1417: =IFERROR(VLOOKUP(Consulta1[[#This Row],[Pozo largo]],Controles!B:H,7,FALSE),"NO") -> 4.64 | L1417: =IFERROR(VLOOKUP(Consulta1[[#This Row],[Pozo largo]],Controles!B:J,9,FALSE),"NO") -> 0
B1418: YPF.SC.CnE-1432 | C1418: CnE-1432 | D1418: Las Heras CG - Canadon Escondida | E1418: Espera Equipo Reparación | F1418: Bombeo Mecánico | G1418: ABA ULT AÑO | H1418: Barranca Baya Bloque 30 | I1418: =IFERROR(VLOOKUP(Consulta1[[#This Row],[Pozo largo]],'Lista YPF'!$B$3:$C$358,2,FALSE),"NO") -> NO | J1418: =IFERROR(VLOOKUP(Consulta1[[#This Row],[Pozo]],'Lista Oportunidades'!B:C,2,FALSE),"NO") -> NO | K1418: =IFERROR(VLOOKUP(Consulta1[[#This Row],[Pozo largo]],Controles!B:H,7,FALSE),"NO") -> 0.3 | L1418: =IFERROR(VLOOKUP(Consulta1[[#This Row],[Pozo largo]],Controles!B:J,9,FALSE),"NO") -> Ultimo Año
B1419: YPF.SC.CnE.a-1125 | C1419: CnE-1125 | D1419: Las Heras CG - Canadon Escondida | E1419: Produciendo | F1419: Bombeo Mecánico | G1419: NO ABANDONAR | H1419: Barranca Baya Bloque 36 | I1419: =IFERROR(VLOOKUP(Consulta1[[#This Row],[Pozo largo]],'Lista YPF'!$B$3:$C$358,2,FALSE),"NO") -> NO | J1419: =IFERROR(VLOOKUP(Consulta1[[#This Row],[Pozo]],'Lista Oportunidades'!B:C,2,FALSE),"NO") -> NO | K1419: =IFERROR(VLOOKUP(Consulta1[[#This Row],[Pozo largo]],Controles!B:H,7,FALSE),"NO") -> 0.72 | L1419: =IFERROR(VLOOKUP(Consulta1[[#This Row],[Pozo largo]],Controles!B:J,9,FALSE),"NO") -> 0
B1420: YPF.SC.LH-1234 | C1420: LH-1234 | D1420: Las Heras CG - Canadon Escondida | E1420: Produciendo | F1420: Bombeo Mecánico | G1420: NO ABANDONAR | H1420: Las Heras Central Sur | I1420: =IFERROR(VLOOKUP(Consulta1[[#This Row],[Pozo largo]],'Lista YPF'!$B$3:$C$358,2,FALSE),"NO") -> NO | J1420: =IFERROR(VLOOKUP(Consulta1[[#This Row],[Pozo]],'Lista Oportunidades'!B:C,2,FALSE),"NO") -> NO | K1420: =IFERROR(VLOOKUP(Consulta1[[#This Row],[Pozo largo]],Controles!B:H,7,FALSE),"NO") -> 0.171 | L1420: =IFERROR(VLOOKUP(Consulta1[[#This Row],[Pozo largo]],Controles!B:J,9,FALSE),"NO") -> 0
B1421: YPF.SC.CnE-1227(d) | C1421: CnE-1227(d)a | D1421: Las Heras CG - Canadon Escondida | E1421: En Estudio | F1421: Pistoneo | G1421: LISTA YPF | H1421: Barranca Baya Bloque 36 | I1421: =IFERROR(VLOOKUP(Consulta1[[#This Row],[Pozo largo]],'Lista YPF'!$B$3:$C$358,2,FALSE),"NO") -> En lista de Abandono | J1421: =IFERROR(VLOOKUP(Consulta1[[#This Row],[Pozo]],'Lista Oportunidades'!B:C,2,FALSE),"NO") -> NO | K1421: =IFERROR(VLOOKUP(Consulta1[[#This Row],[Pozo largo]],Controles!B:H,7,FALSE),"NO") -> 0.048 | L1421: =IFERROR(VLOOKUP(Consulta1[[#This Row],[Pozo largo]],Controles!B:J,9,FALSE),"NO") -> 0
B1422: YPF.SC.CnE-1240 | C1422: CnE-1240 | D1422: Las Heras CG - Canadon Escondida | E1422: Produciendo | F1422: Bombeo Mecánico | G1422: NO ABANDONAR | H1422: Barranca Baya Bloque 36 | I1422: =IFERROR(VLOOKUP(Consulta1[[#This Row],[Pozo largo]],'Lista YPF'!$B$3:$C$358,2,FALSE),"NO") -> NO | J1422: =IFERROR(VLOOKUP(Consulta1[[#This Row],[Pozo]],'Lista Oportunidades'!B:C,2,FALSE),"NO") -> NO | K1422: =IFERROR(VLOOKUP(Consulta1[[#This Row],[Pozo largo]],Controles!B:H,7,FALSE),"NO") -> 2.318 | L1422: =IFERROR(VLOOKUP(Consulta1[[#This Row],[Pozo largo]],Controles!B:J,9,FALSE),"NO") -> 0
B1423: YPF.SC.CnE-1237 | C1423: CnE-1237 | D1423: Las Heras CG - Canadon Escondida | E1423: Reserva Recuperación Secundaria | F1423: Pistoneo | G1423: ABANDONAR | H1423: Barranca Baya Bloque 40 | I1423: =IFERROR(VLOOKUP(Consulta1[[#This Row],[Pozo largo]],'Lista YPF'!$B$3:$C$358,2,FALSE),"NO") -> NO | J1423: =IFERROR(VLOOKUP(Consulta1[[#This Row],[Pozo]],'Lista Oportunidades'!B:C,2,FALSE),"NO") -> NO | K1423: =IFERROR(VLOOKUP(Consulta1[[#This Row],[Pozo largo]],Controles!B:H,7,FALSE),"NO") -> 0.192 | L1423: =IFERROR(VLOOKUP(Consulta1[[#This Row],[Pozo largo]],Controles!B:J,9,FALSE),"NO") -> 0
B1424: YPF.SC.LH-1247 | C1424: LH-1247 | D1424: Las Heras CG - Canadon Escondida | E1424: Produciendo | F1424: Bombeo Mecánico | G1424: NO ABANDONAR | H1424: Las Heras Central Sur | I1424: =IFERROR(VLOOKUP(Consulta1[[#This Row],[Pozo largo]],'Lista YPF'!$B$3:$C$358,2,FALSE),"NO") -> NO | J1424: =IFERROR(VLOOKUP(Consulta1[[#This Row],[Pozo]],'Lista Oportunidades'!B:C,2,FALSE),"NO") -> NO | K1424: =IFERROR(VLOOKUP(Consulta1[[#This Row],[Pozo largo]],Controles!B:H,7,FALSE),"NO") -> 1.176 | L1424: =IFERROR(VLOOKUP(Consulta1[[#This Row],[Pozo largo]],Controles!B:J,9,FALSE),"NO") -> 0
B1425: YPF.SC.CG-727 | C1425: CG-727 | D1425: Las Heras CG - Canadon Escondida | E1425: Produciendo | F1425: Bombeo Mecánico | G1425: NO ABANDONAR | H1425: Cerro Grande Central | I1425: =IFERROR(VLOOKUP(Consulta1[[#This Row],[Pozo largo]],'Lista YPF'!$B$3:$C$358,2,FALSE),"NO") -> NO | J1425: =IFERROR(VLOOKUP(Consulta1[[#This Row],[Pozo]],'Lista Oportunidades'!B:C,2,FALSE),"NO") -> NO | K1425: =IFERROR(VLOOKUP(Consulta1[[#This Row],[Pozo largo]],Controles!B:H,7,FALSE),"NO") -> 0.516 | L1425: =IFERROR(VLOOKUP(Consulta1[[#This Row],[Pozo largo]],Controles!B:J,9,FALSE),"NO") -> 0
B1426: YPF.SC.CG-765 | C1426: CG-765 | D1426: Las Heras CG - Canadon Escondida | E1426: Produciendo | F1426: Bombeo Mecánico | G1426: NO ABANDONAR | H1426: Cerro Grande Central | I1426: =IFERROR(VLOOKUP(Consulta1[[#This Row],[Pozo largo]],'Lista YPF'!$B$3:$C$358,2,FALSE),"NO") -> NO | J1426: =IFERROR(VLOOKUP(Consulta1[[#This Row],[Pozo]],'Lista Oportunidades'!B:C,2,FALSE),"NO") -> NO | K1426: =IFERROR(VLOOKUP(Consulta1[[#This Row],[Pozo largo]],Controles!B:H,7,FALSE),"NO") -> 0.672 | L1426: =IFERROR(VLOOKUP(Consulta1[[#This Row],[Pozo largo]],Controles!B:J,9,FALSE),"NO") -> 0
B1427: YPF.SC.CG-798 | C1427: CG-798 | D1427: Las Heras CG - Canadon Escondida | E1427: Produciendo | F1427: Bombeo Mecánico | G1427: NO ABANDONAR | H1427: Cerro Grande Central | I1427: =IFERROR(VLOOKUP(Consulta1[[#This Row],[Pozo largo]],'Lista YPF'!$B$3:$C$358,2,FALSE),"NO") -> NO | J1427: =IFERROR(VLOOKUP(Consulta1[[#This Row],[Pozo]],'Lista Oportunidades'!B:C,2,FALSE),"NO") -> NO | K1427: =IFERROR(VLOOKUP(Consulta1[[#This Row],[Pozo largo]],Controles!B:H,7,FALSE),"NO") -> 0.7 | L1427: =IFERROR(VLOOKUP(Consulta1[[#This Row],[Pozo largo]],Controles!B:J,9,FALSE),"NO") -> 0
B1428: YPF.SC.CnE.a-1282 | C1428: CnE.a-1282 | D1428: Las Heras CG - Canadon Escondida | E1428: Reserva Recuperación Secundaria | F1428: Bombeo Mecánico | G1428: ABANDONAR | H1428: Barranca Baya Bloque 36 | I1428: =IFERROR(VLOOKUP(Consulta1[[#This Row],[Pozo largo]],'Lista YPF'!$B$3:$C$358,2,FALSE),"NO") -> NO | J1428: =IFERROR(VLOOKUP(Consulta1[[#This Row],[Pozo]],'Lista Oportunidades'!B:C,2,FALSE),"NO") -> NO | K1428: =IFERROR(VLOOKUP(Consulta1[[#This Row],[Pozo largo]],Controles!B:H,7,FALSE),"NO") -> 0.2 | L1428: =IFERROR(VLOOKUP(Consulta1[[#This Row],[Pozo largo]],Controles!B:J,9,FALSE),"NO") -> 0
...

Sheet Lista YPF
B3: YPF.SC.ECa.x-2 | C3: En lista de Abandono
B4: YPF.SC.CG.a-411 | C4: En lista de Abandono
B5: YPF.SC.CG-92 | C5: En lista de Abandono
B6: YPF.SC.CG.a-143 | C6: En lista de Abandono
B7: YPF.SC.ECa.x-3 | C7: En lista de Abandono
B8: YPF.SC.CG-443 | C8: En lista de Abandono
B9: YPF.SC.CG-468 | C9: En lista de Abandono
B10: YPF.SC.CG-482 | C10: En lista de Abandono
B11: YPF.SC.CG-109 | C11: En lista de Abandono
B12: YPF.SC.CG-520 | C12: En lista de Abandono
B13: YPF.SC.CG-459 | C13: En lista de Abandono
B14: YPF.SC.CG.a-23 | C14: En lista de Abandono
... B358: YPF.SC.CG-486 | C358: En lista de Abandono

Sheet Lista Oportunidades
B2: Pozo | C2: Motivo | D2: Estado
B3: CnE-1219 | C3: Oportunidad | D3: =VLOOKUP(B3,Lista!C:G,5,FALSE) -> NO ABANDONAR
B4: CES-4 | C4: Oportunidad | D4: =VLOOKUP(B4,Lista!C:G,5,FALSE) -> ABA O OPORTUNIDAD
B5: LH-694 | C5: Oportunidad | D5: =VLOOKUP(B5,Lista!C:G,5,FALSE) -> NO ABANDONAR
B6: CnE-1279 | C6: Oportunidad | D6: =VLOOKUP(B6,Lista!C:G,5,FALSE) -> NO ABANDONAR
B7: LH-1254 | C7: Oportunidad | D7: =VLOOKUP(B7,Lista!C:G,5,FALSE) -> NO ABANDONAR
B8: CnE.a-1427a | C8: Oportunidad | D8: =VLOOKUP(B8,Lista!C:G,5,FALSE) -> NO ABANDONAR
B9: CnE-652 | C9: Oportunidad | D9: =VLOOKUP(B9,Lista!C:G,5,FALSE) -> ABA O OPORTUNIDAD
B10: CnE-495 | C10: Oportunidad | D10: =VLOOKUP(B10,Lista!C:G,5,FALSE) -> NO ABANDONAR
B11: CG-941 | C11: Oportunidad | D11: =VLOOKUP(B11,Lista!C:G,5,FALSE) -> NO ABANDONAR
B12: ECE-1 | C12: Oportunidad | D12: =VLOOKUP(B12,Lista!C:G,5,FALSE) -> NO ABANDONAR
B13: CnE-806 | C13: Oportunidad | D13: =VLOOKUP(B13,Lista!C:G,5,FALSE) -> ABA O OPORTUNIDAD
B14: CnE-118 | C14: Oportunidad | D14: =VLOOKUP(B14,Lista!C:G,5,FALSE) -> SACAR DE LA LISTA YPF
... B67: CnE-769 | C67: Oportunidad | D67: =VLOOKUP(B67,Lista!C:G,5,FALSE) -> ABA O OPORTUNIDAD

Sheet Controles
A1: UWI_BORE | B1: COMP_NAME | C1: COMP_S_NAME | D1: DIASSINCONTROL | E1: FECHA | F1: QGAS | G1: QWAT | H1: QOIL | I1: RAZON_NOMBRE | J1: Ultimo año
A2: AR0100000798 | B2: YPF.SC.LH-47 | C2: LH-47[00] | D2: 2 | E2: 45973 | F2: 0 | G2: 0.175 | H2: 0.525 | I2: Sale Del Total | J2: Ultimos 6 meses
A3: AR0300007142 | B3: YPF.SC.CnE-1373 | C3: CnE-1373[00] | D3: 144 | E3: 45831 | F3: 0 | G3: 1.5 | H3: 1 | I3: Control A Batería
A4: AR0300034419 | B4: YPF.SC.CG-985 | C4: CG-985 | D4: 50 | E4: 45925 | F4: 526.63 | G4: 65.928 | H4: 4.962 | I4: Control Con Rolo
A5: AR0300035561 | B5: YPF.SC.CnE-1464 | C5: CnE-1464[00]a | D5: 12 | E5: 45963 | F5: 0 | G5: 20.75 | H5: 4.25 | I5: Muestra De Laboratorio
A6: 406020303290 | B6: YPF.SC.CnE-329 | C6: CnE-329[00] | D6: 133 | E6: 45842 | F6: 0 | G6: 29.063 | H6: 0.837 | I6: Control A Batería
A7: 406020301760 | B7: YPF.SC.CnE-176 | C7: CnE-176[00] | D7: 16 | E7: 45959 | F7: 0 | G7: 47.025 | H7: 0.475 | I7: Sale Del Total | J7: Ultimos 6 meses
A8: 406020303730 | B8: YPF.SC.CnE.a-373 | C8: CnE-373[00] | D8: 955 | E8: 45020 | F8: 0 | G8: 0 | H8: 0 | I8: Inyección
A9: 406020304960 | B9: YPF.SC.CnE.a-496 | C9: CnE-496[00] | D9: 726 | E9: 45249 | F9: 0 | G9: 0 | H9: 0 | I9: Inyección
A10: 406020305060 | B10: YPF.SC.CnE-506 | C10: CnE-506[00] | D10: 955 | E10: 45020 | F10: 0 | G10: 0 | H10: 0 | I10: Inyección
A11: 406020305540 | B11: YPF.SC.CnE-554 | C11: CnE-554[00] | D11: 270 | E11: 45705 | F11: 0 | G11: 0.003 | H11: 0.067 | I11: Pistoneo En Casing
A12: 406020305990 | B12: YPF.SC.CnE.a-599 | C12: CnE-599[00] | D12: 23 | E12: 45952 | F12: 0 | G12: 0.001 | H12: 0.029 | I12: Pistoneo En Casing
A13: AR0100010262 | B13: YPF.SC.CnE-1272 | C13: CnE-1272[00] | D13: 16 | E13: 45959 | F13: 0 | G13: 29.1 | H13: 0.9 | I13: Sale Del Total | J13: Ultimos 6 meses
A14: AR0100010274 | B14: YPF.SC.CnE-1284 | C14: CnE-1284[00] | D14: 21 | E14: 45954 | F14: 0 | G14: 10.34 | H14: 0.66 | I14: Sale Del Total | J14: Ultimos 6 meses
A15: 406020307120 | B15: YPF.SC.CnE-712 | C15: CnE-712[00] | D15: 955 | E15: 45020 | F15: 0 | G15: 0 | H15: 0 | I15: Inyección
A16: 406011803420 | B16: YPF.SC.CG-342 | C16: CG-342[00] | D16: 23 | E16: 45952 | F16: 0 | G16: 0.003 | H16: 0.004 | I16: Sale Del Total | J16: Ultimos 6 meses
A17: 406020800450 | B17: YPF.SC.BB-45 | C17: BB-45[00] | D17: 56 | E17: 45919 | F17: 0 | G17: 27.84 | H17: 4.16 | I17: Control A Batería
A18: AR0100004673 | B18: YPF.SC.CnE-894 | C18: CnE-894[00]a | D18: 23 | E18: 45952 | F18: 0 | G18: 2.808 | H18: 0.792 | I18: Sale Del Total | J18: Ultimos 6 meses
A19: AR0100008048 | B19: YPF.SC.CnE-1043 | C19: CnE-1043[00] | D19: 23 | E19: 45952 | F19: 0 | G19: 3.9 | H19: 0.1 | I19: Sale Del Total | J19: Ultimos 6 meses
A20: 406020800760 | B20: YPF.SC.BB.a-76 | C20: BB-76[00] | D20: 25 | E20: 45950 | F20: 0 | G20: 8.6 | H20: 1.4 | I20: Control A Batería
A21: 406020800840 | B21: YPF.SC.BB-84 | C21: BB-84[00] | D21: 955 | E21: 45020 | F21: 0 | G21: 0 | H21: 0 | I21: Inyección
A22: 406020302150 | B22: YPF.SC.CnE-215 | C22: CnE-215[00] | D22: 23 | E22: 45952 | F22: 0 | G22: 47.53 | H22: 1.47 | I22: Sale Del Total | J22: Ultimos 6 meses
A23: AR0100009735 | B23: YPF.SC.CnE-1199(d) | C23: CnE-1199[00](d) | D23: 23 | E23: 45952 | F23: 0 | G23: 0.018 | H23: 0.882 | I23: Sale Del Total | J23: Ultimos 6 meses
A24: AR0100000615 | B24: YPF.SC.BB-24 | C24: BB-24[00] | D24: 78 | E24: 45897 | F24: 0 | G24: 0.1 | H24: 0 | I24: Pistoneo En Casing
A25: AR0100001203 | B25: YPF.SC.CnE-869 | C25: CnE-869[00] | D25: 24 | E25: 45951 | F25: 0 | G25: 0.004 | H25: 0.096 | I25: Sale Del Total | J25: Ultimos 6 meses
A26: AR0100008163 | B26: YPF.SC.CnE-1049 | C26: CnE-1049[00] | D26: 24 | E26: 45951 | F26: 0 | G26: 0.004 | H26: 0.096 | I26: Sale Del Total | J26: Ultimos 6 meses
A27: AR0100000888 | B27: YPF.SC.LH-58 | C27: LH-58[00] | D27: 108 | E27: 45867 | F27: 180 | G27: 2.668 | H27: 1.932 | I27: Merma
A28: AR0100000899 | B28: YPF.SC.LH-95 | C28: LH-95[00] | D28: 25 | E28: 45950 | F28: 100 | G28: 0.078 | H28: 1.222 | I28: Control A Batería
A29: AR0100010187 | B29: YPF.SC.BB-132 | C29: BB-132[00] | D29: 25 | E29: 45950 | F29: 0 | G29: 33.44 | H29: 4.56 | I29: Sale Del Total | J29: Ultimos 6 meses
A30: AR0300026356 | B30: YPF.SC.BB-177 | C30: BB-177[00] | D30: 25 | E30: 45950 | F30: 0 | G30: 3.11 | H30: 1.21 | I30: Sale Del Total | J30: Ultimos 6 meses
A31: AR0300006016 | B31: YPF.SC.CnE-1345 | C31: CnE-1345[00] | D31: 28 | E31: 45947 | F31: 0 | G31: 0.405 | H31: 0.495 | I31: Sale Del Total | J31: Ultimos 6 meses
A32: AR0100001101 | B32: YPF.SC.CG-51 | C32: CG-51[00] | D32: 30 | E32: 45945 | F32: 160 | G32: 5.46 | H32: 2.34 | I32: Sale Del Total | J32: Ultimos 6 meses
A33: AR0100002621 | B33: YPF.SC.LH-972 | C33: LH-972[00]a | D33: 46 | E33: 45929 | F33: 0 | G33: 39.2 | H33: 0.8 | I33: Control A Batería
A34: 406020307690 | B34: YPF.SC.CnE-769 | C34: CnE-769[00] | D34: 30 | E34: 45945 | F34: 0 | G34: 33.25 | H34: 1.75 | I34: Sale Del Total | J34: Ultimos 6 meses
A35: AR0100009500 | B35: YPF.SC.CnE-1111 | C35: CnE-1111[00] | D35: 62 | E35: 45913 | F35: 0 | G35: 8.28 | H35: 0.72 | I35: Tanque Quieto / Cisterna
A36: AR0100009638 | B36: YPF.SC.CnE-1217 | C36: CnE-1217[00] | D36: 955 | E36: 45020 | F36: 0 | G36: 0 | H36: 0 | I36: Inyección
A37: AR0100005326 | B37: YPF.SC.CG-550 | C37: CG-550[00]a | D37: 30 | E37: 45945 | F37: 100 | G37: 0.32 | H37: 1.28 | I37: Sale Del Total | J37: Ultimos 6 meses
A38: AR0100004816 | B38: YPF.SC.LH-1054 | C38: LH-1054[00]a | D38: 32 | E38: 45943 | F38: 0 | G38: 24.75 | H38: 0.25 | I38: Control A Batería
A39: AR0100004317 | B39: YPF.SC.CnE-892 | C39: CnE-892[00]a | D39: 26 | E39: 45949 | F39: 0 | G39: 9.1 | H39: 0.9 | I39: Control A Batería
A40: AR0100005504 | B40: YPF.SC.LH-1088 | C40: LH-1088[00]a | D40: 368 | E40: 45607 | F40: 0 | G40: 0.007 | H40: 0.123 | I40: Pistoneo En Casing
...
